{"id": "7c52b7a26a10", "timestamp": "2025-08-18T22:12:11.673638Z", "severity": "ErrorSeverity.HIGH", "error_type": "ErrorType.UNKNOWN", "source": "ErrorSource.UNKNOWN", "message": "Test error message", "context": {"test": true}, "stack_trace": null, "command": "test command", "exit_code": 1, "file_path": null, "line_number": null}
{"id": "8aacf023bcb6", "timestamp": "2025-08-18T22:12:17.653238Z", "severity": "ErrorSeverity.HIGH", "error_type": "ErrorType.UNKNOWN", "source": "ErrorSource.UNKNOWN", "message": "Test error for validation", "context": {"test": true}, "stack_trace": null, "command": "test command", "exit_code": 1, "file_path": null, "line_number": null}
{"id": "67f501215527", "timestamp": "2025-08-18T22:12:27.142633Z", "severity": "ErrorSeverity.HIGH", "error_type": "ErrorType.SYNTAX", "source": "ErrorSource.UNKNOWN", "message": "SyntaxError: invalid syntax at line 42", "context": {"file": "test.py", "line": 42}, "stack_trace": null, "command": "python test.py", "exit_code": 2, "file_path": null, "line_number": null}
{"id": "49c3a7d8ec4c", "timestamp": "2025-08-18T22:12:31.945346Z", "severity": "ErrorSeverity.HIGH", "error_type": "ErrorType.INTEGRATION", "source": "ErrorSource.UNKNOWN", "message": "Connection refused: database server unavailable", "context": {"server": "db-primary", "port": 5432}, "stack_trace": null, "command": "psql -h db-primary", "exit_code": 1, "file_path": null, "line_number": null}
{"id": "32a81b8fb042", "timestamp": "2025-08-18T22:12:38.863448Z", "severity": "ErrorSeverity.CRITICAL", "error_type": "ErrorType.UNKNOWN", "source": "ErrorSource.UNKNOWN", "message": "Segmentation fault (core dumped)", "context": {"process": "main", "pid": 1234}, "stack_trace": null, "command": null, "exit_code": 139, "file_path": null, "line_number": null}
